Traceback (most recent call last):
  File "/tmp/ai_sys.py", line 25, in initialize_llm
    logger.info("Connected to LLM model: myllm:latest")
NameError: name 'logger' is not defined

During handling of the above exception, another exception occurred:

Traceback (most recent call last):
  File "/tmp/ai_sys.py", line 194, in <module>
    main()
  File "/tmp/ai_sys.py", line 191, in main
    analyzer.interactive_session()
  File "/tmp/ai_sys.py", line 94, in interactive_session
    if not self.initialize_llm():
  File "/tmp/ai_sys.py", line 28, in initialize_llm
    logger.error(f"Failed to connect to LLM: {str(e)}")
NameError: name 'logger' is not defined
